Workbook

Sheet DATOS
A1: INFORME ESTUDIO FV · INARSE — Datos base para gráficas y tablas
A3: BLOQUE 1. INDICADORES PRINCIPALES
A4: Indicador | B4: Valor | C4: Unidad
A5: Energía anual producida | B5: 2769840.9 | C5: kWh
A6: Energía anual producida | B6: 2769.8409 | C6: MWh
A7: Producción media por hora | B7: 316.19189 | C7: kWh/h
A8: Pico horario | B8: 1373.184 | C8: kWh
A9: Fecha/hora del pico | B9: 01-26 10:00
A10: Mejor mes (mayor producción) | B10: ENE
A11: Consumo anual | B11: 2618416.1 | C11: kWh
A12: Balance neto anual | B12: 151.42479 | C12: MWh
A13: Cobertura de la demanda | B13: 40.091233 | C13: %
A14: Excedente potencial | B14: 1720.0856 | C14: MWh
A16: BLOQUE 2. PRODUCCIÓN MENSUAL
A17: Mes | B17: Producción (kWh) | C17: % anual
A18: ENE | B18: 261319.61 | C18: 0.094344626
A19: FEB | B19: 233853.22 | C19: 0.084428394
A20: MAR | B20: 246783.54 | C20: 0.089096648
A21: ABR | B21: 230884.85 | C21: 0.083356719
A22: MAY | B22: 231485.84 | C22: 0.083573694
A23: JUN | B23: 206121.28 | C23: 0.074416288
A24: JUL | B24: 210180.62 | C24: 0.075881839
A25: AGO | B25: 215263.02 | C25: 0.077716745
A26: SEP | B26: 224216.93 | C26: 0.08094939
A27: OCT | B27: 236645.68 | C27: 0.085436559
A28: NOV | B28: 228947.95 | C28: 0.082657435
A29: DIC | B29: 244138.39 | C29: 0.088141663
A30: TOTAL | B30: 2769840.9 | C30: 1
A32: BLOQUE 3. CONSUMO MENSUAL
A33: Mes | B33: Consumo (kWh) | C33: Consumo (MWh)
A34: ENE | B34: 223404.56 | C34: 223.40456
A35: FEB | B35: 200838 | C35: 200.838
A36: MAR | B36: 223404.56 | C36: 223.40456
A37: ABR | B37: 213436.55 | C37: 213.43655
A38: MAY | B38: 223404.56 | C38: 223.40456
A39: JUN | B39: 215882.37 | C39: 215.88237
A40: JUL | B40: 220958.74 | C40: 220.95874
A41: AGO | B41: 223404.56 | C41: 223.40456
A42: SEP | B42: 213436.55 | C42: 213.43655
A43: OCT | B43: 223404.56 | C43: 223.40456
...

Sheet GRAFICAS
A2: Producción mensual
A19: Top 10 días
A36: Mapa mes-hora
A37: Hora | B37: Ene | C37: Feb | D37: Mar | E37: Abr | F37: May | G37: Jun | H37: Jul | I37: Ago | J37: Sep | K37: Oct | L37: Nov | M37: Dic
A38: 0 | B38: =+DATOS!B133 -> 0 | C38: =+DATOS!C133 -> 0 | D38: =+DATOS!D133 -> 0 | E38: =+DATOS!E133 -> 0 | F38: =+DATOS!F133 -> 0 | G38: =+DATOS!G133 -> 0 | H38: =+DATOS!H133 -> 0 | I38: =+DATOS!I133 -> 0 | ... M38: =+DATOS!M133 -> 0
A39: 1 | B39: =+DATOS!B134 -> 0 | C39: =+DATOS!C134 -> 0 | D39: =+DATOS!D134 -> 0 | E39: =+DATOS!E134 -> 0 | F39: =+DATOS!F134 -> 0 | G39: =+DATOS!G134 -> 0 | H39: =+DATOS!H134 -> 0 | I39: =+DATOS!I134 -> 0 | ... M39: =+DATOS!M134 -> 0
A40: 2 | B40: =+DATOS!B135 -> 0 | C40: =+DATOS!C135 -> 0 | D40: =+DATOS!D135 -> 0 | E40: =+DATOS!E135 -> 0 | F40: =+DATOS!F135 -> 0 | G40: =+DATOS!G135 -> 0 | H40: =+DATOS!H135 -> 0 | I40: =+DATOS!I135 -> 0 | ... M40: =+DATOS!M135 -> 0
A41: 3 | B41: =+DATOS!B136 -> 0 | C41: =+DATOS!C136 -> 0 | D41: =+DATOS!D136 -> 0 | E41: =+DATOS!E136 -> 0 | F41: =+DATOS!F136 -> 0 | G41: =+DATOS!G136 -> 0 | H41: =+DATOS!H136 -> 0 | I41: =+DATOS!I136 -> 0 | ... M41: =+DATOS!M136 -> 0
A42: 4 | B42: =+DATOS!B137 -> 0 | C42: =+DATOS!C137 -> 0 | D42: =+DATOS!D137 -> 0 | E42: =+DATOS!E137 -> 0.068682353 | F42: =+DATOS!F137 -> 1.0549298 | G42: =+DATOS!G137 -> 0.037658824 | H42: =+DATOS!H137 -> 0 | I42: =+DATOS!I137 -> 0 | ... M42: =+DATOS!M137 -> 1.7929298
A43: 5 | B43: =+DATOS!B138 -> 162.3323 | C43: =+DATOS!C138 -> 140.99616 | D43: =+DATOS!D138 -> 143.83663 | E43: =+DATOS!E138 -> 168.84131 | F43: =+DATOS!F138 -> 177.16427 | G43: =+DATOS!G138 -> 140.92948 | H43: =+DATOS!H138 -> 107.14727 | I43: =+DATOS!I138 -> 124.62428 | ... M43: =+DATOS!M138 -> 217.14513
A44: 6 | B44: =+DATOS!B139 -> 498.964 | C44: =+DATOS!C139 -> 459.36911 | D44: =+DATOS!D139 -> 439.99589 | E44: =+DATOS!E139 -> 453.05241 | F44: =+DATOS!F139 -> 465.11348 | G44: =+DATOS!G139 -> 381.18918 | H44: =+DATOS!H139 -> 337.17928 | I44: =+DATOS!I139 -> 361.54356 | ... M44: =+DATOS!M139 -> 510.75369
A45: 7 | B45: =+DATOS!B140 -> 784.72035 | C45: =+DATOS!C140 -> 755.80166 | D45: =+DATOS!D140 -> 726.47242 | E45: =+DATOS!E140 -> 737.88335 | F45: =+DATOS!F140 -> 732.61496 | G45: =+DATOS!G140 -> 622.00041 | H45: =+DATOS!H140 -> 579.36784 | I45: =+DATOS!I140 -> 620.64755 | ... M45: =+DATOS!M140 -> 773.89186
A46: 8 | B46: =+DATOS!B141 -> 1032.1955 | C46: =+DATOS!C141 -> 1009.6339 | D46: =+DATOS!D141 -> 952.31531 | E46: =+DATOS!E141 -> 940.62907 | F46: =+DATOS!F141 -> 959.56261 | G46: =+DATOS!G141 -> 842.48531 | H46: =+DATOS!H141 -> 788.09277 | I46: =+DATOS!I141 -> 838.60818 | ... M46: =+DATOS!M141 -> 977.31465
A47: 9 | B47: =+DATOS!B142 -> 1154.6333 | C47: =+DATOS!C142 -> 1164.1268 | D47: =+DATOS!D142 -> 1103.2699 | E47: =+DATOS!E142 -> 1070.7997 | F47: =+DATOS!F142 -> 1068.0514 | G47: =+DATOS!G142 -> 967.0926 | H47: =+DATOS!H142 -> 925.68433 | I47: =+DATOS!I142 -> 966.56581 | ... M47: =+DATOS!M142 -> 1083.6792
A48: 10 | B48: =+DATOS!B143 -> 1212.6399 | C48: =+DATOS!C143 -> 1201.7147 | D48: =+DATOS!D143 -> 1158.5665 | E48: =+DATOS!E143 -> 1091.2504 | F48: =+DATOS!F143 -> 1067.7511 | G48: =+DATOS!G143 -> 1002.5592 | H48: =+DATOS!H143 -> 967.38233 | I48: =+DATOS!I143 -> 998.1844 | ... M48: =+DATOS!M143 -> 1102.0405
A49: 11 | B49: =+DATOS!B144 -> 1144.6856 | C49: =+DATOS!C144 -> 1142.4764 | D49: =+DATOS!D144 -> 1130.0145 | E49: =+DATOS!E144 -> 1058.292 | F49: =+DATOS!F144 -> 1015.4348 | G49: =+DATOS!G144 -> 942.75191 | H49: =+DATOS!H144 -> 959.08191 | I49: =+DATOS!I144 -> 965.89749 | ... M49: =+DATOS!M144 -> 1076.1789
... A61: 23 | B61: =+DATOS!B156 -> 0 | C61: =+DATOS!C156 -> 0 | D61: =+DATOS!D156 -> 0 | E61: =+DATOS!E156 -> 0 | F61: =+DATOS!F156 -> 0 | G61: =+DATOS!G156 -> 0 | H61: =+DATOS!H156 -> 0 | I61: =+DATOS!I156 -> 0 | ... M61: =+DATOS!M156 -> 0
A62: Mapa de calor: filas = hora del día; columnas = mes; valores en kWh medios por hora.
A65: Indicador | E65: Valor
A66: Energía anual media (kWh) | E66: =+DATOS!B5 -> 2769840.9
A67: Energía anual media (MWh) | E67: =+DATOS!B6 -> 2769.8409
A68: Producción media por hora (kWh) | E68: =+DATOS!B7 -> 316.19189
A69: Pico horario (kWh) | E69: =+DATOS!B8 -> 1373.184
A70: Fecha/hora del pico | E70: 02-07 10:00
A71: Mejor mes | E71: =+CONCATENATE(DATOS!B10," (",DATOS!B9,")",) -> ENE (01-26 10:00)
A73: Nombre | C73: Energía media (kWh) | E73: % anual
A74: Enero | C74: =+DATOS!B18 -> 261319.61 | E74: =+DATOS!C18 -> 0.094344626
A75: Febrero | C75: =+DATOS!B19 -> 233853.22 | E75: =+DATOS!C19 -> 0.084428394
A76: Marzo | C76: =+DATOS!B20 -> 246783.54 | E76: =+DATOS!C20 -> 0.089096648
A77: Abril | C77: =+DATOS!B21 -> 230884.85 | E77: =+DATOS!C21 -> 0.083356719
A78: Mayo | C78: =+DATOS!B22 -> 231485.84 | E78: =+DATOS!C22 -> 0.083573694
A79: Junio | C79: =+DATOS!B23 -> 206121.28 | E79: =+DATOS!C23 -> 0.074416288
A80: Julio | C80: =+DATOS!B24 -> 210180.62 | E80: =+DATOS!C24 -> 0.075881839
A81: Agosto | C81: =+DATOS!B25 -> 215263.02 | E81: =+DATOS!C25 -> 0.077716745
A82: Septiembre | C82: =+DATOS!B26 -> 224216.93 | E82: =+DATOS!C26 -> 0.08094939
A83: Octubre | C83: =+DATOS!B27 -> 236645.68 | E83: =+DATOS!C27 -> 0.085436559
A84: Noviembre | C84: =+DATOS!B28 -> 228947.95 | E84: =+DATOS!C28 -> 0.082657435
A85: Diciembre | C85: =+DATOS!B29 -> 244138.39 | E85: =+DATOS!C29 -> 0.088141663
A91: Producción vs consumo mensual
A110: Balance mensual
...
